Workbook
Name CountryCode: [1]Contents!$B$8
Name curdb: [2]Content!$E$5

Sheet Calibration
C1: Parameter Description | E1: Parameters | F1: Values
A2: Calibration | B2: Country-specific parameters and moments | C2: Public infrastructure investment to GDP ratio | E2: iziy | F2: 0.013
C3: Public adaptation infrastructure investment to GDP ratio | E3: izay | F3: 0
C4: Consumption tax rate (VAT) | E4: ho | F4: 0.125
C5: Labor income tax rate | E5: hlo | F5: 0.2
C6: Public domestic debt to GDP ratio | E6: share_b | F6: 0.077
C7: Public concessional debt to GDP ratio | E7: share_d | F7: 0.129
C8: Public external commercial debt to GDP ratio | E8: share_dc | F8: 0.05
C9: Private external debt to GDP ratio | E9: share_bstar | F9: 0
C10: Real interest rate on public domestic debt | E10: ro | F10: 0.05
C11: Real interest rate on public external commercial debt | E11: r_dco | F11: 0.015
C12: Grants to GDP ratio | E12: share_grants | F12: 0.112
C13: Natural resources revenue to GDP ratio | E13: oilro | F13: 0
C14: Remittances to GDP ratio | E14: share_remit | F14: 0.035
... C24: Capital's share in value added in the NT-sector | E24: alpha_n | F24: 0.4
B25: Parameters determining main characteristics of standard and adaptation infrastructure | C25: Scaling parameter determining ability of adaptation capital to withstand natural disaster (see Realism sheet) | E25: ppi_nd_n | F25: 25
C26: Cost ratio adaptation vs standard investment [adaptation is % expensive than standard] | E26: a_za | F26: 0.25
C27: Initial return standard on infrastructure investment | E27: R_zio | F27: 0.3
C28: Initial return on adaptation infrastructure investment | E28: R_zao | F28: 0.5
C29: Depreciation rate of public capital (standard infrastructure) | E29: delta_zi | F29: 0.03
C30: Depreciation rate of public capital (adaptation) | E30: delta_za | F30: 0.075
C31: Speed of reconstruction of public standard infrastructure | E31: pgamma_zi | F31: 0.5
C32: Speed of recovery of public investment efficiency | E32: pgamma_s | F32: 0.5
C33: Speed of recovery of tradable sector TFP | E33: pgamma_ax | F33: 0.5
C34: Speed of recovery of country risk premium | E34: pgamma_rdc | F34: 0.5
C35: User fees for infrastructure services (% of recurrent costs) | E35: fo | F35: 0.05
B36: Fiscal adjustment parameters | C36: Division of fiscal adjustment parameter - Transfers | E36: lambda | F36: 0.2
C37: Division of fiscal adjustment parameter - Consumption tax | E37: lambda_h | F37: 0.4
C38: Division of fiscal adjustment parameter -Labor income tax | E38: lambda_hl | F38: 0.4
C39: Share of public debt adj. between commercial external and domestic (=1 when only domestic debt is used) | E39: upsilon | F39: 0.5
C40: Fiscal reaction parameter (policy instrument terms) - Consumption VAT | E40: lambda1 | F40: 0.5
C41: Fiscal reaction parameter (debt terms) - Consumption VAT | E41: lambda2 | F41: 0.5
C42: Fiscal reaction parameter (policy instrument terms) - Transfers | E42: lambda3 | F42: 0.5
C43: Fiscal reaction parameter (debt terms) - Transfers | E43: lambda4 | F43: 0.5
C44: Fiscal reaction parameter (policy instrument terms) - Labor income tax | E44: lambda5 | F44: 0.5
C45: Fiscal reaction parameter (debt terms) - Labor income tax | E45: lambda6 | F45: 0.5
B46: Other structural parametrs | C46: Risk-free foreign RIR (r^f) | E46: rstar | F46: 0.04
C47: Depreciation rate in T-sector | E47: delta_x | F47: 0.05
C48: Depreciation rate in NT-sector | E48: delta_n | F48: 0.05
C49: Intertemporal elasticity of substitution | E49: tau | F49: 0.34
...

Sheet Exogenous_series
B1: Period | C1: Year | D1: Option 1 | L1: Option 2 | T1: Option 3
D2: Public Infrastructure Investment (% of Initial GDP) | E2: Public Adaptation Investment (% of Initial GDP) | F2: Delta Contingency Fund (% of Initial GDP) | G2: Grants (% of Initial GDP) | H2: Concessional Debt (% of Initial GDP) | I2: Terms of trade shock | L2: Public Infrastructure Investment (% of Initial GDP) | M2: Public Adaptation Investment (% of Initial GDP) | N2: Delta Contingency Fund (% of Initial GDP) | O2: Grants (% of Initial GDP) | P2: Concessional Debt (% of Initial GDP) | Q2: Terms of trade shock | T2: Public Infrastructure Investment (% of Initial GDP) | U2: Public Adaptation Investment (% of Initial GDP) | V2: Delta Contingency Fund (% of Initial GDP) | W2: Grants (% of Initial GDP) | X2: Concessional Debt (% of Initial GDP) | Y2: Terms of trade shock
I3: Price of Exported Goods (Index) | J3: Price of Imported Consumption Goods (Index) | K3: Price of Imported Capital Goods (Index) | Q3: Price of Exported Goods (Index) | R3: Price of Imported Consumption Goods (Index) | S3: Price of Imported Capital Goods (Index) | Y3: Price of Exported Goods (Index) | Z3: Price of Imported Consumption Goods (Index) | AA3: Price of Imported Capital Goods (Index)
A4: Exogenous series | B4: 1 | C4: =Disasters!D4-Disasters!C4+1 -> 2022 | D4: 0 | E4: 1 | F4: 0 | G4: 1 | H4: 0 | I4: 0 | J4: 0 | K4: 0 | L4: 1 | M4: 0 | N4: 0 | O4: 1 | P4: 0 | Q4: 0 | R4: 0 | S4: 0 | T4: 0 | U4: 2 | V4: 0 | W4: 1 | X4: 1 | Y4: 0 | Z4: 0 | AA4: 0
B5: =+B4+1 -> 2 | C5: =C4+1 -> 2023 | D5: 0 | E5: 1 | F5: 0 | G5: 1 | H5: 0 | I5: 0 | J5: 0 | K5: 0 | L5: 1 | M5: 0 | N5: 0 | O5: 1 | P5: 0 | Q5: 0 | R5: 0 | S5: 0 | T5: 0 | U5: 2 | V5: 0 | W5: 1 | X5: 1 | Y5: 0 | Z5: 0 | AA5: 0
B6: =+B5+1 -> 3 | C6: =+C5+1 -> 2024 | D6: 0 | E6: 1 | F6: 0 | G6: 1 | H6: 0 | I6: 0 | J6: 0 | K6: 0 | L6: 1 | M6: 0 | N6: 0 | O6: 1 | P6: 0 | Q6: 0 | R6: 0 | S6: 0 | T6: 0 | U6: 2 | V6: 0 | W6: 1 | X6: 1 | Y6: 0 | Z6: 0 | AA6: 0
B7: =+B6+1 -> 4 | C7: =+C6+1 -> 2025 | D7: 0 | E7: 1 | F7: 0 | G7: 1 | H7: 0 | I7: 0 | J7: 0 | K7: 0 | L7: 1 | M7: 0 | N7: 0 | O7: 1 | P7: 0 | Q7: 0 | R7: 0 | S7: 0 | T7: 0 | U7: 2 | V7: 0 | W7: 1 | X7: 1 | Y7: 0 | Z7: 0 | AA7: 0
B8: =+B7+1 -> 5 | C8: =+C7+1 -> 2026 | D8: 0 | E8: 1 | F8: 0 | G8: 1 | H8: 0 | I8: 0 | J8: 0 | K8: 0 | L8: 1 | M8: 0 | N8: 0 | O8: 1 | P8: 0 | Q8: 0 | R8: 0 | S8: 0 | T8: 0 | U8: 2 | V8: 0 | W8: 1 | X8: 1 | Y8: 0 | Z8: 0 | AA8: 0
B9: =+B8+1 -> 6 | C9: =+C8+1 -> 2027 | D9: 0 | E9: 0 | F9: 0 | G9: 0 | H9: 0 | I9: 0 | J9: 0 | K9: 0 | L9: 0 | M9: 0 | N9: 0 | O9: 0 | P9: 0 | Q9: 0 | R9: 0 | S9: 0 | T9: 0 | U9: 0 | V9: 0 | W9: 0 | X9: 0 | Y9: 0 | Z9: 0 | AA9: 0
B10: =+B9+1 -> 7 | C10: =+C9+1 -> 2028 | D10: 0 | E10: 0 | F10: 0 | G10: 0 | H10: 0 | I10: 0 | J10: 0 | K10: 0 | L10: 0 | M10: 0 | N10: 0 | O10: 0 | P10: 0 | Q10: 0 | R10: 0 | S10: 0 | T10: 0 | U10: 0 | V10: 0 | W10: 0 | X10: 0 | Y10: 0 | Z10: 0 | AA10: 0
B11: =+B10+1 -> 8 | C11: =+C10+1 -> 2029 | D11: 0 | E11: 0 | F11: 0 | G11: 0 | H11: 0 | I11: 0 | J11: 0 | K11: 0 | L11: 0 | M11: 0 | N11: 0 | O11: 0 | P11: 0 | Q11: 0 | R11: 0 | S11: 0 | T11: 0 | U11: 0 | V11: 0 | W11: 0 | X11: 0 | Y11: 0 | Z11: 0 | AA11: 0
B12: =+B11+1 -> 9 | C12: =+C11+1 -> 2030 | D12: 0 | E12: 0 | F12: 0 | G12: 0 | H12: 0 | I12: 0 | J12: 0 | K12: 0 | L12: 0 | M12: 0 | N12: 0 | O12: 0 | P12: 0 | Q12: 0 | R12: 0 | S12: 0 | T12: 0 | U12: 0 | V12: 0 | W12: 0 | X12: 0 | Y12: 0 | Z12: 0 | AA12: 0
B13: =+B12+1 -> 10 | C13: =+C12+1 -> 2031 | D13: 0 | E13: 0 | F13: 0 | G13: 0 | H13: 0 | I13: 0 | J13: 0 | K13: 0 | L13: 0 | M13: 0 | N13: 0 | O13: 0 | P13: 0 | Q13: 0 | R13: 0 | S13: 0 | T13: 0 | U13: 0 | V13: 0 | W13: 0 | X13: 0 | Y13: 0 | Z13: 0 | AA13: 0
B14: =+B13+1 -> 11 | C14: =+C13+1 -> 2032 | D14: 0 | E14: 0 | F14: 0 | G14: 0 | H14: 0 | I14: 0 | J14: 0 | K14: 0 | L14: 0 | M14: 0 | N14: 0 | O14: 0 | P14: 0 | Q14: 0 | R14: 0 | S14: 0 | T14: 0 | U14: 0 | V14: 0 | W14: 0 | X14: 0 | Y14: 0 | Z14: 0 | AA14: 0
B15: =+B14+1 -> 12 | C15: =+C14+1 -> 2033 | D15: 0 | E15: 0 | F15: 0 | G15: 0 | H15: 0 | I15: 0 | J15: 0 | K15: 0 | L15: 0 | M15: 0 | N15: 0 | O15: 0 | P15: 0 | Q15: 0 | R15: 0 | S15: 0 | T15: 0 | U15: 0 | V15: 0 | W15: 0 | X15: 0 | Y15: 0 | Z15: 0 | AA15: 0
B16: =+B15+1 -> 13 | C16: =+C15+1 -> 2034 | D16: 0 | E16: 0 | F16: 0 | G16: 0 | H16: 0 | I16: 0 | J16: 0 | K16: 0 | L16: 0 | M16: 0 | N16: 0 | O16: 0 | P16: 0 | Q16: 0 | R16: 0 | S16: 0 | T16: 0 | U16: 0 | V16: 0 | W16: 0 | X16: 0 | Y16: 0 | Z16: 0 | AA16: 0
B17: =+B16+1 -> 14 | C17: =+C16+1 -> 2035 | D17: 0 | E17: 0 | F17: 0 | G17: 0 | H17: 0 | I17: 0 | J17: 0 | K17: 0 | L17: 0 | M17: 0 | N17: 0 | O17: 0 | P17: 0 | Q17: 0 | R17: 0 | S17: 0 | T17: 0 | U17: 0 | V17: 0 | W17: 0 | X17: 0 | Y17: 0 | Z17: 0 | AA17: 0
... B38: =+B37+1 -> 35 | C38: =+C37+1 -> 2056 | D38: 0 | E38: 0 | F38: 0 | G38: 0 | H38: 0 | I38: 0 | J38: 0 | K38: 0 | L38: 0 | M38: 0 | N38: 0 | O38: 0 | P38: 0 | Q38: 0 | R38: 0 | S38: 0 | T38: 0 | U38: 0 | V38: 0 | W38: 0 | X38: 0 | Y38: 0 | Z38: 0 | AA38: 0
B39: =+B38+1 -> 36 | C39: =+C38+1 -> 2057
B40: =+B39+1 -> 37 | C40: =+C39+1 -> 2058
B41: =+B40+1 -> 38 | C41: =+C40+1 -> 2059
B42: =+B41+1 -> 39 | C42: =+C41+1 -> 2060
B43: =+B42+1 -> 40 | C43: =+C42+1 -> 2061
B44: =+B43+1 -> 41 | C44: =+C43+1 -> 2062
B45: =+B44+1 -> 42 | C45: =+C44+1 -> 2063
B46: =+B45+1 -> 43 | C46: =+C45+1 -> 2064
B47: =+B46+1 -> 44 | C47: =+C46+1 -> 2065
B48: =+B47+1 -> 45 | C48: =+C47+1 -> 2066
B49: =+B48+1 -> 46 | C49: =+C48+1 -> 2067
B50: =+B49+1 -> 47 | C50: =+C49+1 -> 2068
... B53: =+B52+1 -> 50 | C53: =+C52+1 -> 2071

Sheet Scenario
B1: Define how financing is achieved in each scenario | E1: Define which exogenous series are used in each scenario (From Exogeneous_series sheet) | F1: Option | G1: Periods | H1: Define name of shock | I1: PIE Reform Target
B2: Financing 1 | C2: all_debt | E2: Scenario 1 | F2: 1 | G2: 20 | H2: Baseline Adaptation | I2: =Calibration!F20 -> 0.5 | BT2: yes
B3: Financing 2 | E3: Scenario 2 | F3: 2 | G3: 20 | H3: Baseline Standard | I3: 0.5 | BT3: no
B4: Financing 3 | E4: Scenario 3 | F4: 3 | G4: 20 | H4: Adaptation & PIE | I4: 0.7
A7: Scenarios | B7: Label | C7: Debt scenarios
B8: all_debt | C8: Public domestic and external commercial debt are allowed to cover the fiscal gap, in addition to the path for concessional debt and grants specified in the 'Exogenous_series' worksheet. (define upsilon in Calibration)
B9: domestic_debt | C9: Public domestic debt is allowed to cover the fiscal gap, while public external commercial debt is held constant.
B10: commercial_debt | C10: Public external commercial debt is allowed to cover the fiscal gap, while public domestic debt and fiscal instuments are held constant.
B11: exogeneous | C11: The entire fiscal gap is covered by fiscal instuments (labor tax, consumption tax, and cash transfers) conditional on exogenous paths for grants and concessional debt (supplied in the 'Exogenous_series' worksheet).
A14: Note: | I14: 0

Sheet Disasters
C2: Period | D2: Year
B3: Would you like to incorporate a natural disaster? | C3: yes | AQ3: yes
B4: In which period does the natural disaster strike? | C4: 6 | D4: 2027 | AQ4: no
A6: Impact of natural disaster | B6: Natural disaster scenario | D6: Damages and losses
B7: Impact of natural disaster on tradable output? Specify destruction in %. | D7: 0.2
B8: Impact of natural disaster on nontradable output? Specify destruction in %. | D8: 0.2
B9: Impact of natural disaster on reconstruction efficiency (%) | D9: 0
B10: Impact of natural disaster on external public debt risk premium? (increase in percentage points) | D10: 0
B11: Impact of natural disaster on public capital (% of GDP) | D11: 0.2
B12: Impact of natural disaster on private capital (% of GDP) | D12: 0.2
B13: Share of damages to tradable sector capital (% total private capital damages) | D13: 0.5
A16: Recovery Periods | B16: Loss of productivity | C16: Traded sector TFP | D16: Nontraded sector TFP
B17: When does the recovery start? | C17: 2027 | D17: =C17 -> 2027
B18: Year in which recovery is complete? | C18: 2032 | D18: =C18 -> 2032
B19: Efficiency for reconstruction
B20: When does the recovery start? | C20: =C17 -> 2027
B21: Year in which recovery is complete? | C21: =C18 -> 2032
B22: Public capital reconstruction
B23: When does the recovery start? | C23: =C20 -> 2027
B24: Year in which recovery is complete? | C24: =C21 -> 2032
B25: External debt risk premium
B26: When does the recovery start? | C26: =C23 -> 2027
B27: Year in which recovery is complete? | C27: =C24 -> 2032

Sheet Graphs
A1: Graphs | B1: Graph Description | C1: 'yes' or 'no' (case sensitive) | D1: Number of periods to plot | E1: Number of rows | F1: Number of columns | G1: Number of variables allowed to be plotted | H1: Number of variables being plotted | I1: Variable 1 | J1: Variable 2 | K1: Variable 3 | L1: Variable 4 | M1: Variable 5 | N1: Variable 6 | O1: Variable 7 | P1: Variable 8 | Q1: Variable 9 | R1: Variable 10 | S1: Variable 11 | T1: Variable 12 | U1: Variable 13 | V1: Variable 14 | W1: Variable 15 | X1: Variable 16
B2: Graph 1. Comparing debt financing scenarios for each calibration selected | C2: no | D2: 25 | E2: 3 | F2: 4 | G2: =+E2*F2 -> 12 | H2: =COUNTA(I2:X2) -> 15 | I2: pubinvgdp | J2: pubadapgdp | K2: rgdp | L2: fiscaldef | M2: cadef | N2: privconsgr | O2: privinvgr | P2: curexpgdp | Q2: domdebtgdp | R2: totpubdebt | S2: commdebtgdp | T2: concdebtgdp | U2: a_x | V2: a_n | W2: hpercent | BV2: yes
B3: Plot each financing option in a separate chart | C3: yes | D3: 20 | E3: 4 | F3: 4 | G3: =+E3*F3 -> 16 | H3: =COUNTA(I3:X3) -> 16 | I3: zi | J3: k | K3: a_n | L3: a_x | M3: pubinvgdp | N3: s | O3: rextgpercent | P3: hpercent | Q3: totpubdebt | R3: grantsgdp | S3: privconsgr | T3: privinvgr | U3: cadef | V3: savgdp | W3: rgdp | X3: pubadapgdp | BV3: no
B7: Variables available to graph | C7: Label
B8: Public Infrastructure Investment (% of GDP) | C8: pubinvgdp
B9: Public Infrastructure Adaptation Investment (% of GDP) | C9: pubadapgdp
B10: Real GDP Growth (% dev from SS) | C10: rgdp
B11: Private Investment Growth (% dev from SS) | C11: privinvgr
B12: Domestic Public Debt (% of GDP) | C12: domdebtgdp
B13: Concessional Debt (% of GDP) | C13: concdebtgdp
B14: Total Public Debt (% of GDP) | C14: totpubdebt
B15: Fiscal Deficit (% of GDP) | C15: fiscaldef
B16: Grants (% of GDP) | C16: grantsgdp
B17: Public Effective Standard Capital (level) | C17: zie
B18: Public Effective Adaptation Capital (level) | C18: zae
... B35: Real Wages (% dev from SS) | C35: rwages

Sheet XLSoutput
A1: XLS | B1: Excel output | C1: yes' or 'no' (case sensitive) | D1: Number of periods to export | E1: Number of variables being exported | F1: Variable 1 | G1: Variable 2 | H1: Variable 3 | I1: Variable 4 | J1: Variable 5 | K1: Variable 6 | L1: Variable 7 | M1: Variable 8 | N1: Variable 9 | O1: Variable 10 | P1: Variable 11 | Q1: Variable 12 | R1: Variable 13 | S1: Variable 14 | T1: Variable 15 | U1: Variable 16
B2: Would you like to have the time series of selected variables exported to Excel? | C2: yes | D2: 20 | E2: =COUNTA(F2:U2) -> 16 | F2: zi | G2: k | H2: a_n | I2: a_x | J2: pubinvgdp | K2: s | L2: rextgpercent | M2: hpercent | N2: totpubdebt | O2: grantsgdp | P2: privconsgr | Q2: privinvgr | R2: cadef | S2: savgdp | T2: rgdp | U2: pubadapgdp | BS2: yes
BS3: no
B7: Variables available to export | C7: Label
B8: Public Infrastructure Investment (% of GDP) | C8: pubinvgdp
B9: Public Infrastructure Adaptation Investment (% of GDP) | C9: pubadapgdp
B10: Real GDP Growth (% dev from SS) | C10: rgdp
B11: Private Investment Growth (% dev from SS) | C11: privinvgr
B12: Domestic Public Debt (% of GDP) | C12: domdebtgdp
B13: Concessional Debt (% of GDP) | C13: concdebtgdp
B14: Total Public Debt (% of GDP) | C14: totpubdebt
B15: Fiscal Deficit (% of GDP) | C15: fiscaldef
B16: Grants (% of GDP) | C16: grantsgdp
B17: Public Effective Standard Capital (level) | C17: zie
B18: Public Effective Adaptation Capital (level) | C18: zae
... B35: Real Wages (% dev from SS) | C35: rwages

Sheet Realism
A1: Parameter | C1: Values | G1: Adaptation capital to initial year GDP (percent) | H1: Disaster damage mitigated by adaptation capital (percent)
A2: Scaling parameter in ability of adaptation capital to withstand natural disaster | C2: Low | D2: Baseline | E2: High | H2: Low | I2: Baseline | J2: High
C3: =D3/2 -> 12.5 | D3: =Calibration!F25 -> 25 | E3: =D3*2 -> 50 | G3: 0 | H3: =(1-1/((1+$C$3*$G3)^(1))) -> 0 | I3: =(1-1/((1+$D$3*$G3)^(1))) -> 0 | J3: =(1-1/((1+$E$3*$G3)^(1))) -> 0
G4: =G3+0.005 -> 0.005 | H4: =(1-1/((1+$C$3*$G4)^(1))) -> 0.058823529 | I4: =(1-1/((1+$D$3*$G4)^(1))) -> 0.11111111 | J4: =(1-1/((1+$E$3*$G4)^(1))) -> 0.2
G5: =G4+0.005 -> 0.01 | H5: =(1-1/((1+$C$3*$G5)^(1))) -> 0.11111111 | I5: =(1-1/((1+$D$3*$G5)^(1))) -> 0.2 | J5: =(1-1/((1+$E$3*$G5)^(1))) -> 0.33333333
A6: Year | B6: Approximate level of adaptation capital (based on exogenous series) | G6: =G5+0.005 -> 0.015 | H6: =(1-1/((1+$C$3*$G6)^(1))) -> 0.15789474 | I6: =(1-1/((1+$D$3*$G6)^(1))) -> 0.27272727 | J6: =(1-1/((1+$E$3*$G6)^(1))) -> 0.42857143
G7: =G6+0.005 -> 0.02 | H7: =(1-1/((1+$C$3*$G7)^(1))) -> 0.2 | I7: =(1-1/((1+$D$3*$G7)^(1))) -> 0.33333333 | J7: =(1-1/((1+$E$3*$G7)^(1))) -> 0.5
G8: =G7+0.005 -> 0.025 | H8: =(1-1/((1+$C$3*$G8)^(1))) -> 0.23809524 | I8: =(1-1/((1+$D$3*$G8)^(1))) -> 0.38461538 | J8: =(1-1/((1+$E$3*$G8)^(1))) -> 0.55555556
B9: Option 1 | C9: Option 2 | D9: Option 3 | G9: =G8+0.005 -> 0.03 | H9: =(1-1/((1+$C$3*$G9)^(1))) -> 0.27272727 | I9: =(1-1/((1+$D$3*$G9)^(1))) -> 0.42857143 | J9: =(1-1/((1+$E$3*$G9)^(1))) -> 0.6
A10: =Exogenous_series!C4-1 -> 2021 | B10: =(Calibration!$F$20*Calibration!$F$3/(Calibration!$F$30+Calibration!$F$17))/100 -> 0 | C10: =(Calibration!$F$20*Calibration!$F$3/(Calibration!$F$30+Calibration!$F$17))/100 -> 0 | D10: =(Calibration!$F$20*Calibration!$F$3/(Calibration!$F$30+Calibration!$F$17))/100 -> 0 | G10: =G9+0.005 -> 0.035 | H10: =(1-1/((1+$C$3*$G10)^(1))) -> 0.30434783 | I10: =(1-1/((1+$D$3*$G10)^(1))) -> 0.46666667 | J10: =(1-1/((1+$E$3*$G10)^(1))) -> 0.63636364
A11: =A10+1 -> 2022 | B11: =(B10*(1-Calibration!$F$30)+Calibration!$F$20*(Calibration!$F$3+Exogenous_series!E4)/100) -> 0.005 | C11: =(C10*(1-Calibration!$F$30)+Calibration!$F$20*(Calibration!$F$3+Exogenous_series!M4)/100) -> 0 | D11: =(D10*(1-Calibration!$F$30)+Calibration!$F$20*(Calibration!$F$3+Exogenous_series!U4)/100) -> 0.01 | G11: =G10+0.005 -> 0.04 | H11: =(1-1/((1+$C$3*$G11)^(1))) -> 0.33333333 | I11: =(1-1/((1+$D$3*$G11)^(1))) -> 0.5 | J11: =(1-1/((1+$E$3*$G11)^(1))) -> 0.66666667
A12: =A11+1 -> 2023 | B12: =(B11*(1-Calibration!$F$30)+Calibration!$F$20*(Calibration!$F$3+Exogenous_series!E5)/100) -> 0.009625 | C12: =(C11*(1-Calibration!$F$30)+Calibration!$F$20*(Calibration!$F$3+Exogenous_series!M5)/100) -> 0 | D12: =(D11*(1-Calibration!$F$30)+Calibration!$F$20*(Calibration!$F$3+Exogenous_series!U5)/100) -> 0.01925 | G12: =G11+0.005 -> 0.045 | H12: =(1-1/((1+$C$3*$G12)^(1))) -> 0.36 | I12: =(1-1/((1+$D$3*$G12)^(1))) -> 0.52941176 | J12: =(1-1/((1+$E$3*$G12)^(1))) -> 0.69230769
A13: =A12+1 -> 2024 | B13: =(B12*(1-Calibration!$F$30)+Calibration!$F$20*(Calibration!$F$3+Exogenous_series!E6)/100) -> 0.013903125 | C13: =(C12*(1-Calibration!$F$30)+Calibration!$F$20*(Calibration!$F$3+Exogenous_series!M6)/100) -> 0 | D13: =(D12*(1-Calibration!$F$30)+Calibration!$F$20*(Calibration!$F$3+Exogenous_series!U6)/100) -> 0.02780625 | G13: =G12+0.005 -> 0.05 | H13: =(1-1/((1+$C$3*$G13)^(1))) -> 0.38461538 | I13: =(1-1/((1+$D$3*$G13)^(1))) -> 0.55555556 | J13: =(1-1/((1+$E$3*$G13)^(1))) -> 0.71428571
A14: =A13+1 -> 2025 | B14: =(B13*(1-Calibration!$F$30)+Calibration!$F$20*(Calibration!$F$3+Exogenous_series!E7)/100) -> 0.017860391 | C14: =(C13*(1-Calibration!$F$30)+Calibration!$F$20*(Calibration!$F$3+Exogenous_series!M7)/100) -> 0 | D14: =(D13*(1-Calibration!$F$30)+Calibration!$F$20*(Calibration!$F$3+Exogenous_series!U7)/100) -> 0.035720781 | G14: =G13+0.005 -> 0.055 | H14: =(1-1/((1+$C$3*$G14)^(1))) -> 0.40740741 | I14: =(1-1/((1+$D$3*$G14)^(1))) -> 0.57894737 | J14: =(1-1/((1+$E$3*$G14)^(1))) -> 0.73333333
A15: =A14+1 -> 2026 | B15: =(B14*(1-Calibration!$F$30)+Calibration!$F$20*(Calibration!$F$3+Exogenous_series!E8)/100) -> 0.021520861 | C15: =(C14*(1-Calibration!$F$30)+Calibration!$F$20*(Calibration!$F$3+Exogenous_series!M8)/100) -> 0 | D15: =(D14*(1-Calibration!$F$30)+Calibration!$F$20*(Calibration!$F$3+Exogenous_series!U8)/100) -> 0.043041723 | G15: =G14+0.005 -> 0.06 | H15: =(1-1/((1+$C$3*$G15)^(1))) -> 0.42857143 | I15: =(1-1/((1+$D$3*$G15)^(1))) -> 0.6 | J15: =(1-1/((1+$E$3*$G15)^(1))) -> 0.75
A16: =A15+1 -> 2027 | B16: =(B15*(1-Calibration!$F$30)+Calibration!$F$20*(Calibration!$F$3+Exogenous_series!E9)/100) -> 0.019906797 | C16: =(C15*(1-Calibration!$F$30)+Calibration!$F$20*(Calibration!$F$3+Exogenous_series!M9)/100) -> 0 | D16: =(D15*(1-Calibration!$F$30)+Calibration!$F$20*(Calibration!$F$3+Exogenous_series!U9)/100) -> 0.039813593 | G16: =G15+0.005 -> 0.065 | H16: =(1-1/((1+$C$3*$G16)^(1))) -> 0.44827586 | I16: =(1-1/((1+$D$3*$G16)^(1))) -> 0.61904762 | J16: =(1-1/((1+$E$3*$G16)^(1))) -> 0.76470588
A17: =A16+1 -> 2028 | B17: =(B16*(1-Calibration!$F$30)+Calibration!$F$20*(Calibration!$F$3+Exogenous_series!E10)/100) -> 0.018413787 | C17: =(C16*(1-Calibration!$F$30)+Calibration!$F$20*(Calibration!$F$3+Exogenous_series!M10)/100) -> 0 | D17: =(D16*(1-Calibration!$F$30)+Calibration!$F$20*(Calibration!$F$3+Exogenous_series!U10)/100) -> 0.036827574 | G17: =G16+0.005 -> 0.07 | H17: =(1-1/((1+$C$3*$G17)^(1))) -> 0.46666667 | I17: =(1-1/((1+$D$3*$G17)^(1))) -> 0.63636364 | J17: =(1-1/((1+$E$3*$G17)^(1))) -> 0.77777778
A18: =A17+1 -> 2029 | B18: =(B17*(1-Calibration!$F$30)+Calibration!$F$20*(Calibration!$F$3+Exogenous_series!E11)/100) -> 0.017032753 | C18: =(C17*(1-Calibration!$F$30)+Calibration!$F$20*(Calibration!$F$3+Exogenous_series!M11)/100) -> 0 | D18: =(D17*(1-Calibration!$F$30)+Calibration!$F$20*(Calibration!$F$3+Exogenous_series!U11)/100) -> 0.034065506 | G18: =G17+0.005 -> 0.075 | H18: =(1-1/((1+$C$3*$G18)^(1))) -> 0.48387097 | I18: =(1-1/((1+$D$3*$G18)^(1))) -> 0.65217391 | J18: =(1-1/((1+$E$3*$G18)^(1))) -> 0.78947368
A19: =A18+1 -> 2030 | B19: =(B18*(1-Calibration!$F$30)+Calibration!$F$20*(Calibration!$F$3+Exogenous_series!E12)/100) -> 0.015755296 | C19: =(C18*(1-Calibration!$F$30)+Calibration!$F$20*(Calibration!$F$3+Exogenous_series!M12)/100) -> 0 | D19: =(D18*(1-Calibration!$F$30)+Calibration!$F$20*(Calibration!$F$3+Exogenous_series!U12)/100) -> 0.031510593 | G19: =G18+0.005 -> 0.08 | H19: =(1-1/((1+$C$3*$G19)^(1))) -> 0.5 | I19: =(1-1/((1+$D$3*$G19)^(1))) -> 0.66666667 | J19: =(1-1/((1+$E$3*$G19)^(1))) -> 0.8
A20: =A19+1 -> 2031 | B20: =(B19*(1-Calibration!$F$30)+Calibration!$F$20*(Calibration!$F$3+Exogenous_series!E13)/100) -> 0.014573649 | C20: =(C19*(1-Calibration!$F$30)+Calibration!$F$20*(Calibration!$F$3+Exogenous_series!M13)/100) -> 0 | D20: =(D19*(1-Calibration!$F$30)+Calibration!$F$20*(Calibration!$F$3+Exogenous_series!U13)/100) -> 0.029147298 | G20: =G19+0.005 -> 0.085 | H20: =(1-1/((1+$C$3*$G20)^(1))) -> 0.51515152 | I20: =(1-1/((1+$D$3*$G20)^(1))) -> 0.68 | J20: =(1-1/((1+$E$3*$G20)^(1))) -> 0.80952381
A21: =A20+1 -> 2032 | B21: =(B20*(1-Calibration!$F$30)+Calibration!$F$20*(Calibration!$F$3+Exogenous_series!E14)/100) -> 0.013480626 | C21: =(C20*(1-Calibration!$F$30)+Calibration!$F$20*(Calibration!$F$3+Exogenous_series!M14)/100) -> 0 | D21: =(D20*(1-Calibration!$F$30)+Calibration!$F$20*(Calibration!$F$3+Exogenous_series!U14)/100) -> 0.026961251 | G21: =G20+0.005 -> 0.09 | H21: =(1-1/((1+$C$3*$G21)^(1))) -> 0.52941176 | I21: =(1-1/((1+$D$3*$G21)^(1))) -> 0.69230769 | J21: =(1-1/((1+$E$3*$G21)^(1))) -> 0.81818182
A22: =A21+1 -> 2033 | B22: =(B21*(1-Calibration!$F$30)+Calibration!$F$20*(Calibration!$F$3+Exogenous_series!E15)/100) -> 0.012469579 | C22: =(C21*(1-Calibration!$F$30)+Calibration!$F$20*(Calibration!$F$3+Exogenous_series!M15)/100) -> 0 | D22: =(D21*(1-Calibration!$F$30)+Calibration!$F$20*(Calibration!$F$3+Exogenous_series!U15)/100) -> 0.024939157 | G22: =G21+0.005 -> 0.095 | H22: =(1-1/((1+$C$3*$G22)^(1))) -> 0.54285714 | I22: =(1-1/((1+$D$3*$G22)^(1))) -> 0.7037037 | J22: =(1-1/((1+$E$3*$G22)^(1))) -> 0.82608696
... A39: =A38+1 -> 2050 | B39: =(B38*(1-Calibration!$F$30)+Calibration!$F$20*(Calibration!$F$3+Exogenous_series!E32)/100) -> 0.0033133036 | C39: =(C38*(1-Calibration!$F$30)+Calibration!$F$20*(Calibration!$F$3+Exogenous_series!M32)/100) -> 0 | D39: =(D38*(1-Calibration!$F$30)+Calibration!$F$20*(Calibration!$F$3+Exogenous_series!U32)/100) -> 0.0066266072 | G39: =G38+0.005 -> 0.18 | H39: =(1-1/((1+$C$3*$G39)^(1))) -> 0.69230769 | I39: =(1-1/((1+$D$3*$G39)^(1))) -> 0.81818182 | J39: =(1-1/((1+$E$3*$G39)^(1))) -> 0.9
A41: Note:
A42: 1. Uses only Financing 1 from Scenario worksheet. Please use "all_debt" scenario.
A43: 2. Uses only Option 1 from Exogenous_series worksheet.
A44: 3. Do not change BASELINE value (it is taken from CALIBRATION worksheet)!

Sheet Alignment
A1: Year | B1: real GDP | D1: Alignment tool
B2: (percent deviation from initial year) | D2: Do you wish to use shocks generated by the Alignment tool? (No = 0; Yes = 1) | E2: 0
A3: 2021 | B3: 0
A4: =A3+1 -> 2022 | B4: 0 | D4: Note:
A5: =A4+1 -> 2023 | B5: 0 | D5: 1. Uses only Financing 1 from Scenario worksheet.
A6: =A5+1 -> 2024 | B6: 0 | D6: 2. Assumes NO shocks from exogenous series worksheet.
A7: =A6+1 -> 2025 | B7: 0 | D7: 3. If you wish to use shocks generated by the Alignment tool, after you run alignment module insert "1" (cell "E2") and run simulate again.
A8: =A7+1 -> 2026 | B8: -12.7951
A9: =A8+1 -> 2027 | B9: -14.8044
A10: =A9+1 -> 2028 | B10: -10.6064
A11: =A10+1 -> 2029 | B11: -7.8366
A12: =A11+1 -> 2030 | B12: -6.0582
A13: =A12+1 -> 2031 | B13: -3.2278
A14: =A13+1 -> 2032 | B14: -2.9643
A15: =A14+1 -> 2033 | B15: -1
A16: =A15+1 -> 2034 | B16: 0
A17: =A16+1 -> 2035 | B17: 0
A18: =A17+1 -> 2036 | B18: 0
A19: =A18+1 -> 2037 | B19: 0
... A32: =A31+1 -> 2050 | B32: 0

Sheet Donor_Savings
B1: Donor Savings
B4: Description | C4: Values | E4: Please enter the country specific data before running the module
B5: Baseline GDP (initial year, in billions US$) | C5: 100
B6: Discount rate for calculation Net Present Value (NPV) | C6: 0.05
B8: Note:
B9: 1. Uses only Financing 1 from Scenario worksheet.
B10: 2. Uses only Option 1 from Exogenous_series worksheet.

Sheet Disclaimer
A2: DISCLAIMER: This manual for DIGNAD toolkit should not be reported as representing the views of the IMF. The views expressed here are those of the authors and do not necessarily represent the views of the IMF, its Executive Board, or IMF management.
A5: This toolkit is part of a research project on macroeconomic policy in low-income countries (IATI Identifier: GB-1-202960) supported by the U.K.’s Foreign, Commonwealth and Development Office (FCDO) and the partners in the IMF’s COVID-19 Crisis Capacity Development Initiative (CCCDI)—Belgium, Canada, China, Germany, Japan, Korea, Singapore, Spain, and Switzerland. The outputs, analyses, and views expressed herein are those of the authors and should not be attributed to the IMF, its Executive Board, its management, the FCDO, or the partners in the CCCDI.
A11: IMF Copyright and Usage terms
A12: IMF Copyright and Usage terms govern the provision of the DIGNAD Toolkit and associated content. | K12: https://www.imf.org/external/terms.htm
A13: Inclusion of or reference to third-party software in the DIGNAD Toolkit does not represent or imply sponsorship, approval or endorsement of the software by the IMF.
A14: Users are responsible for using any third-party software referenced in the DIGNAD Toolkit in accordance with the terms of use associated with each software.
A16: Dynare
A17: Dynare is a software platform for handling a wide class of economic models, in particular dynamic stochastic general equilibrium (DSGE) and overlapping generations (OLG) models. Dynare is a free software, which means that it can be downloaded free of charge, that its source code is freely available, and that it can be used for both non-profit and for-profit purposes. Most of the source files are covered by the GNU General Public Licence (GPL) version 3 or later (see license.txt in Dynare distribution). It is available for the Windows, macOS, and Linux platforms and is fully documented through a reference manual.
A21: Stéphane Adjemian, Houtan Bastani, Michel Juillard, Frédéric Karamé, Ferhat Mihoubi, Willi Mutschler, Johannes Pfeifer, Marco Ratto, Normann Rion and Sébastien Villemot (2022), “Dynare: Reference Manual, Version 5,” Dynare Working Papers, 72, CEPREMAP.
A23: Copyright © 1996-2022, Dynare Team.
A25: CompEcon Toolbox
A26: CompEcon is a set of MATLAB functions for solving a variety of problems in economics and finance. The CompEcon Toolbox was developed to accompany:
A27: Applied Computational Economics and Finance, Mario J. Miranda & Paul L. Fackler, MIT Press. 2002
A28: For additional information or to report any problems, please visit: | H28: CompEcon Toolbox for Matlab
E30: For any questions or comments, please contact | J30: dignad@imf.org
